<?xml version="1.0" ?>
<!-- =================================================================================== -->
<!-- |    This document was autogenerated by xacro from panda_arm_hand.urdf.xacro      | -->
<!-- |    EDITING THIS FILE BY HAND IS NOT RECOMMENDED                                 | -->
<!-- =================================================================================== -->
<robot name="panda" xmlns:xacro="http://www.ros.org/wiki/xacro">
  <link name="panda_link0">
  	<inertial>
      <origin rpy="0 0 0" xyz="0 0 0.05"/>
       <mass value="2.9"/>
       <inertia ixx="0.1" ixy="0" ixz="0" iyy="0.1" iyz="0" izz="0.1"/>
    </inertial>
    <visual>
      <geometry>
        <mesh filename="meshes/collision/link0.obj"/>
      </geometry>
      <material name="panda_white">
    		<color rgba="1. 1. 1. 1."/>
  		</material>
    </visual>
    <collision>
      <geometry>
        <mesh filename="meshes/collision/link0.obj"/>
      </geometry>
      <material name="panda_white"/>
    </collision>
  </link>
  <link name="panda_link1">
  	<inertial>
      <origin rpy="0 0 0" xyz="0 -0.04 -0.05"/>
       <mass value="2.7"/>
       <inertia ixx="0.1" ixy="0" ixz="0" iyy="0.1" iyz="0" izz="0.1"/>
    </inertial>
    <visual>
      <geometry>
        <mesh filename="meshes/visual/link1.obj"/>
      </geometry>
      <material name="panda_white"/>
    </visual>
    <collision>
      <geometry>
        <mesh filename="meshes/collision/link1.obj"/>
      </geometry>
      <material name="panda_white"/>
    </collision>
  </link>
  <joint name="panda_joint1" type="revolute">
    <safety_controller k_position="100.0" k_velocity="40.0" soft_lower_limit="-2.8973" soft_upper_limit="2.8973"/>
    <origin rpy="0 0 0" xyz="0 0 0.333"/>
    <parent link="panda_link0"/>
    <child link="panda_link1"/>
    <axis xyz="0 0 1"/>
        <limit effort="87" lower="-2.9671" upper="2.9671" velocity="2.3925" />
  </joint>
  <link name="panda_link2">
  	<inertial>
      <origin rpy="0 0 0" xyz="0 -0.04 0.06"/>
       <mass value="2.73"/>
       <inertia ixx="0.1" ixy="0" ixz="0" iyy="0.1" iyz="0" izz="0.1"/>
    </inertial>
    <visual>
      <geometry>
        <mesh filename="meshes/visual/link2.obj"/>
      </geometry>
      <material name="panda_white"/>
    </visual>
    <collision>
      <geometry>
        <mesh filename="meshes/collision/link2.obj"/>
      </geometry>
      <material name="panda_white"/>
    </collision>
  </link>
  <joint name="panda_joint2" type="revolute">
    <safety_controller k_position="100.0" k_velocity="40.0" soft_lower_limit="-1.7628" soft_upper_limit="1.7628"/>
    <origin rpy="-1.57079632679 0 0" xyz="0 0 0"/>
    <parent link="panda_link1"/>
    <child link="panda_link2"/>
    <axis xyz="0 0 1"/>
        <limit effort="87" lower="-1.8326" upper="1.8326" velocity="2.3925" />
  </joint>
  <link name="panda_link3">
	  <inertial>
      <origin rpy="0 0 0" xyz="0.01 0.01 -0.05"/>
       <mass value="2.04"/>
       <inertia ixx="0.1" ixy="0" ixz="0" iyy="0.1" iyz="0" izz="0.1"/>
    </inertial>
    <visual>
      <geometry>
        <mesh filename="meshes/visual/link3.obj"/>
      </geometry>
      <material name="panda_red">
    		<color rgba="1. 1. 1. 1."/>
  		</material>
    </visual>
    <collision>
      <geometry>
        <mesh filename="meshes/collision/link3.obj"/>
      </geometry>
    </collision>
  </link>
  <joint name="panda_joint3" type="revolute">
    <safety_controller k_position="100.0" k_velocity="40.0" soft_lower_limit="-2.8973" soft_upper_limit="2.8973"/>
    <origin rpy="1.57079632679 0 0" xyz="0 -0.316 0"/>
    <parent link="panda_link2"/>
    <child link="panda_link3"/>
    <axis xyz="0 0 1"/>
        <limit effort="87" lower="-2.9671" upper="2.9671" velocity="2.3925" />
  </joint>
  <link name="panda_link4">
  	<inertial>
      <origin rpy="0 0 0" xyz="-0.03 0.03 0.02"/>
       <mass value="2.08"/>
       <inertia ixx="0.1" ixy="0" ixz="0" iyy="0.1" iyz="0" izz="0.1"/>
    </inertial>
    <visual>
      <geometry>
        <mesh filename="meshes/visual/link4.obj"/>
      </geometry>
      <material name="panda_white"/>
    </visual>
    <collision>
      <geometry>
        <mesh filename="meshes/collision/link4.obj"/>
      </geometry>
      <material name="panda_white"/>
    </collision>
  </link>
  <joint name="panda_joint4" type="revolute">
    <safety_controller k_position="100.0" k_velocity="40.0" soft_lower_limit="-3.0718" soft_upper_limit="-0.0698"/>
    <origin rpy="1.57079632679 0 0" xyz="0.0825 0 0"/>
    <parent link="panda_link3"/>
    <child link="panda_link4"/>
    <axis xyz="0 0 1"/>
        <limit effort="87" lower="-3.1416" upper="0.0873" velocity="2.3925" />
  </joint>
  <link name="panda_link5">
  	<inertial>
      <origin rpy="0 0 0" xyz="0 0.04 -0.12"/>
       <mass value="3"/>
       <inertia ixx="0.1" ixy="0" ixz="0" iyy="0.1" iyz="0" izz="0.1"/>
    </inertial>
    <visual>
      <geometry>
        <mesh filename="meshes/visual/link5.obj"/>
      </geometry>
      <material name="panda_white"/>
    </visual>
    <collision>
      <geometry>
        <mesh filename="meshes/collision/link5.obj"/>
      </geometry>
      <material name="panda_white"/>
    </collision>
  </link>
  <joint name="panda_joint5" type="revolute">
    <safety_controller k_position="100.0" k_velocity="40.0" soft_lower_limit="-2.8973" soft_upper_limit="2.8973"/>
    <origin rpy="-1.57079632679 0 0" xyz="-0.0825 0.384 0"/>
    <parent link="panda_link4"/>
    <child link="panda_link5"/>
    <axis xyz="0 0 1"/>
        <limit effort="12" lower="-2.9671" upper="2.9671" velocity="2.8710" />
  </joint>
  <link name="panda_link6">
  	<inertial>
      <origin rpy="0 0 0" xyz="0.04 0 0"/>
       <mass value="1.3"/>
       <inertia ixx="0.1" ixy="0" ixz="0" iyy="0.1" iyz="0" izz="0.1"/>
    </inertial>
    <visual>
      <geometry>
        <mesh filename="meshes/visual/link6.obj"/>
      </geometry>
      <material name="panda_white"/>
    </visual>
    <collision>
      <geometry>
        <mesh filename="meshes/collision/link6.obj"/>
      </geometry>
      <material name="panda_white"/>
    </collision>
  </link>
  <joint name="panda_joint6" type="revolute">
    <safety_controller k_position="100.0" k_velocity="40.0" soft_lower_limit="-0.0175" soft_upper_limit="3.7525"/>
    <origin rpy="1.57079632679 0 0" xyz="0 0 0"/>
    <parent link="panda_link5"/>
    <child link="panda_link6"/>
    <axis xyz="0 0 1"/>
        <limit effort="12" lower="-0.0873" upper="3.8223" velocity="2.8710" />
  </joint>
  <link name="panda_link7">
  	<inertial>
      <origin rpy="0 0 0" xyz="0 0 0.08"/>
       <mass value=".2"/>
       <inertia ixx="0.1" ixy="0" ixz="0" iyy="0.1" iyz="0" izz="0.1"/>
    </inertial>
    <visual>
      <geometry>
        <mesh filename="meshes/collision/link7.obj"/>
      </geometry>
      <material name="panda_white"/>
    </visual>
    <collision>
      <geometry>
        <mesh filename="meshes/collision/link7.obj"/>
      </geometry>
      <material name="panda_white"/>
    </collision>
  </link>
  <joint name="panda_joint7" type="revolute">
    <safety_controller k_position="100.0" k_velocity="40.0" soft_lower_limit="-2.8973" soft_upper_limit="2.8973"/>
    <origin rpy="1.57079632679 0 0" xyz="0.088 0 0"/>
    <parent link="panda_link6"/>
    <child link="panda_link7"/>
    <axis xyz="0 0 1"/>
        <limit effort="12" lower="-2.9671" upper="2.9671" velocity="2.8710" />
  </joint>
  <link name="panda_link8">
  	 <inertial>
      <origin rpy="0 0 0" xyz="0 0 0"/>
       <mass value="0.0"/>
       <inertia ixx="0.1" ixy="0" ixz="0" iyy="0.1" iyz="0" izz="0.1"/>
    </inertial>
  </link>
  <joint name="panda_joint8" type="fixed">
    <origin rpy="0 0 0" xyz="0 0 0.107"/>
    <parent link="panda_link7"/>
    <child link="panda_link8"/>
    <axis xyz="0 0 0"/>
  </joint>
  <joint name="panda_hand_joint" type="fixed">
    <parent link="panda_link8"/>
    <child link="panda_hand"/>
    <origin rpy="0 0 -0.785398163397" xyz="0 0 0"/>
  </joint>
  <link name="panda_hand">
  	<inertial>
      <origin rpy="0 0 0" xyz="0 0 0.04"/>
       <mass value=".81"/>
       <inertia ixx="0.1" ixy="0" ixz="0" iyy="0.1" iyz="0" izz="0.1"/>
    </inertial>
    <visual>
      <geometry>
        <mesh filename="meshes/visual/hand.obj"/>
      </geometry>
      <material name="panda_white"/>
    </visual>
    <collision>
      <geometry>
        <mesh filename="meshes/collision/hand.obj"/>
      </geometry>
      <material name="panda_white"/>
    </collision>
  </link>
  
  <link name="panda_marker_holder">
  
  <inertial>
    <origin xyz="0 0 0.02" rpy="0 0 0"/>
    <mass value="0.2"/>
    <inertia ixx="0.001" ixy="0" ixz="0"
             iyy="0.001" iyz="0"
             izz="0.001"/>
  </inertial>

  <visual>
    <geometry>
      <mesh filename="meshes/visual/marker_holder.obj"/>
    </geometry>
    <material name="panda_white"/>
  </visual>

  <collision>
    <geometry>
      <mesh filename="meshes/collision/marker_holder.obj"/>
    </geometry>
  </collision>
</link>

  
   <link name="panda_marker">
   
  <inertial>
    <origin xyz="0 0 0.05" rpy="0 0 0"/>
    <mass value="0.05"/>
    <inertia ixx="0.0002" ixy="0" ixz="0"
             iyy="0.0002" iyz="0"
             izz="0.0002"/>
  </inertial>

  <visual>
    <geometry>
      <mesh filename="meshes/visual/marker.obj"/>
    </geometry>
    <material name="marker_black"/>
  </visual>

  <collision>
    <geometry>
      <mesh filename="meshes/collision/marker.obj"/>
    </geometry>
  </collision>
</link>

<joint name="panda_marker_holder_joint" type="fixed">
  <parent link="panda_hand"/>
  <child link="panda_marker_holder"/>
  <origin xyz="-0.01 -0.032 0.065" rpy="0 0 0"/>
</joint>

<joint name="panda_marker_joint" type="fixed">
  <parent link="panda_marker_holder"/>
  <child link="panda_marker"/>
  <origin xyz="-0.075 0.0285 0.15" rpy="-1.57079632679 0 0"/>
</joint>
<link name="panda_tip">
  <inertial>
    <origin xyz="0 0 0.02" rpy="0 0 0"/>
    <mass value="0.01"/>
    <inertia ixx="0.00005" ixy="0" ixz="0"
             iyy="0.00005" iyz="0"
             izz="0.00005"/>
  </inertial>

  <visual>
    <geometry>
      <mesh filename="meshes/visual/tip.obj"/>
    </geometry>
    <material name="marker_black"/>
  </visual>

  <collision>
    <geometry>
      <mesh filename="meshes/collision/tip.obj"/>
    </geometry>
  </collision>
</link>

<joint name="panda_tip_joint" type="fixed">
  <parent link="panda_marker"/>
  <child link="panda_tip"/>
  <origin xyz="0.08125 0.0035 0.003625" rpy="0 0 0"/>
</joint>

  
</robot>
